Traceback (most recent call last):
  File "C:\miniconda\envs\psqlpy_venv\lib\site-packages\jupyter_cache\executors\utils.py", line 58, in single_nb_execution
    executenb(
  File "C:\miniconda\envs\psqlpy_venv\lib\site-packages\nbclient\client.py", line 1314, in execute
    return NotebookClient(nb=nb, resources=resources, km=km, **kwargs).execute()
  File "C:\miniconda\envs\psqlpy_venv\lib\site-packages\jupyter_core\utils\__init__.py", line 98, in wrapped
    return loop.run_until_complete(inner)
  File "C:\miniconda\envs\psqlpy_venv\lib\asyncio\base_events.py", line 647, in run_until_complete
    return future.result()
  File "C:\miniconda\envs\psqlpy_venv\lib\site-packages\nbclient\client.py", line 709, in async_execute
    await self.async_execute_cell(
  File "C:\miniconda\envs\psqlpy_venv\lib\site-packages\nbclient\client.py", line 1062, in async_execute_cell
    await self._check_raise_for_error(cell, cell_index, exec_reply)
  File "C:\miniconda\envs\psqlpy_venv\lib\site-packages\nbclient\client.py", line 918, in _check_raise_for_error
    raise CellExecutionError.from_cell_and_msg(cell, exec_reply_content)
nbclient.exceptions.CellExecutionError: An error occurred while executing the following cell:
------------------
connection =psycopg2.connect(database="myname_db", user="myname_user", password="password", host="localhost", port="5432")
cursor=connection.cursor()
------------------


[1;31m---------------------------------------------------------------------------[0m
[1;31mOperationalError[0m                          Traceback (most recent call last)
Cell [1;32mIn[2], line 1[0m
[1;32m----> 1[0m connection [38;5;241m=[39m[43mpsycopg2[49m[38;5;241;43m.[39;49m[43mconnect[49m[43m([49m[43mdatabase[49m[38;5;241;43m=[39;49m[38;5;124;43m"[39;49m[38;5;124;43mmyname_db[39;49m[38;5;124;43m"[39;49m[43m,[49m[43m [49m[43muser[49m[38;5;241;43m=[39;49m[38;5;124;43m"[39;49m[38;5;124;43mmyname_user[39;49m[38;5;124;43m"[39;49m[43m,[49m[43m [49m[43mpassword[49m[38;5;241;43m=[39;49m[38;5;124;43m"[39;49m[38;5;124;43mpassword[39;49m[38;5;124;43m"[39;49m[43m,[49m[43m [49m[43mhost[49m[38;5;241;43m=[39;49m[38;5;124;43m"[39;49m[38;5;124;43mlocalhost[39;49m[38;5;124;43m"[39;49m[43m,[49m[43m [49m[43mport[49m[38;5;241;43m=[39;49m[38;5;124;43m"[39;49m[38;5;124;43m5432[39;49m[38;5;124;43m"[39;49m[43m)[49m
[0;32m      2[0m cursor[38;5;241m=[39mconnection[38;5;241m.[39mcursor()

File [1;32mC:\miniconda\envs\psqlpy_venv\lib\site-packages\psycopg2\__init__.py:122[0m, in [0;36mconnect[1;34m(dsn, connection_factory, cursor_factory, **kwargs)[0m
[0;32m    119[0m     kwasync[[38;5;124m'[39m[38;5;124masync_[39m[38;5;124m'[39m] [38;5;241m=[39m kwargs[38;5;241m.[39mpop([38;5;124m'[39m[38;5;124masync_[39m[38;5;124m'[39m)
[0;32m    121[0m dsn [38;5;241m=[39m _ext[38;5;241m.[39mmake_dsn(dsn, [38;5;241m*[39m[38;5;241m*[39mkwargs)
[1;32m--> 122[0m conn [38;5;241m=[39m _connect(dsn, connection_factory[38;5;241m=[39mconnection_factory, [38;5;241m*[39m[38;5;241m*[39mkwasync)
[0;32m    123[0m [38;5;28;01mif[39;00m cursor_factory [38;5;129;01mis[39;00m [38;5;129;01mnot[39;00m [38;5;28;01mNone[39;00m:
[0;32m    124[0m     conn[38;5;241m.[39mcursor_factory [38;5;241m=[39m cursor_factory

[1;31mOperationalError[0m: connection to server at "localhost" (::1), port 5432 failed: Connection refused (0x0000274D/10061)
	Is the server running on that host and accepting TCP/IP connections?
connection to server at "localhost" (127.0.0.1), port 5432 failed: Connection refused (0x0000274D/10061)
	Is the server running on that host and accepting TCP/IP connections?


